Results of doctest builder run on 2016-07-11 11:06:08
=====================================================

Document: pyhpeimc.auth
-----------------------
**********************************************************************
File "pyhpeimc.auth.rst", line 5, in default
Failed example:
    auth = IMCAuth("http://", "10.101.0.203", "8080", "admin", "admin")
Exception raised:
    Traceback (most recent call last):
      File "/Library/Frameworks/Python.framework/Versions/3.4/lib/python3.4/doctest.py", line 1318, in __run
        compileflags, 1), test.globs)
      File "<doctest default[0]>", line 1, in <module>
        auth = IMCAuth("http://", "10.101.0.203", "8080", "admin", "admin")
    NameError: name 'IMCAuth' is not defined
**********************************************************************
File "pyhpeimc.auth.rst", line 8, in default
Failed example:
    auth.password
Exception raised:
    Traceback (most recent call last):
      File "/Library/Frameworks/Python.framework/Versions/3.4/lib/python3.4/doctest.py", line 1318, in __run
        compileflags, 1), test.globs)
      File "<doctest default[0]>", line 1, in <module>
        auth.password
    NameError: name 'auth' is not defined
**********************************************************************
1 items had failures:
   2 of   2 in default
2 tests in 1 items.
0 passed and 2 failed.
***Test Failed*** 2 failures.

Document: pyhpeimc.plat.device
------------------------------
**********************************************************************
File "pyhpeimc.plat.device.rst", line ?, in default
Failed example:
    get_dev_details('10.101.0.1', auth.creds, auth.url)
Exception raised:
    Traceback (most recent call last):
      File "/Library/Frameworks/Python.framework/Versions/3.4/lib/python3.4/site-packages/requests/packages/urllib3/connection.py", line 142, in _new_conn
        (self.host, self.port), self.timeout, **extra_kw)
      File "/Library/Frameworks/Python.framework/Versions/3.4/lib/python3.4/site-packages/requests/packages/urllib3/util/connection.py", line 91, in create_connection
        raise err
      File "/Library/Frameworks/Python.framework/Versions/3.4/lib/python3.4/site-packages/requests/packages/urllib3/util/connection.py", line 81, in create_connection
        sock.connect(sa)
    TimeoutError: [Errno 60] Operation timed out

    During handling of the above exception, another exception occurred:

    Traceback (most recent call last):
      File "/Library/Frameworks/Python.framework/Versions/3.4/lib/python3.4/site-packages/requests/packages/urllib3/connectionpool.py", line 578, in urlopen
        chunked=chunked)
      File "/Library/Frameworks/Python.framework/Versions/3.4/lib/python3.4/site-packages/requests/packages/urllib3/connectionpool.py", line 362, in _make_request
        conn.request(method, url, **httplib_request_kw)
      File "/Library/Frameworks/Python.framework/Versions/3.4/lib/python3.4/http/client.py", line 1088, in request
        self._send_request(method, url, body, headers)
      File "/Library/Frameworks/Python.framework/Versions/3.4/lib/python3.4/http/client.py", line 1126, in _send_request
        self.endheaders(body)
      File "/Library/Frameworks/Python.framework/Versions/3.4/lib/python3.4/http/client.py", line 1084, in endheaders
        self._send_output(message_body)
      File "/Library/Frameworks/Python.framework/Versions/3.4/lib/python3.4/http/client.py", line 922, in _send_output
        self.send(msg)
      File "/Library/Frameworks/Python.framework/Versions/3.4/lib/python3.4/http/client.py", line 857, in send
        self.connect()
      File "/Library/Frameworks/Python.framework/Versions/3.4/lib/python3.4/site-packages/requests/packages/urllib3/connection.py", line 167, in connect
        conn = self._new_conn()
      File "/Library/Frameworks/Python.framework/Versions/3.4/lib/python3.4/site-packages/requests/packages/urllib3/connection.py", line 151, in _new_conn
        self, "Failed to establish a new connection: %s" % e)
    requests.packages.urllib3.exceptions.NewConnectionError: <requests.packages.urllib3.connection.HTTPConnection object at 0x1031af1d0>: Failed to establish a new connection: [Errno 60] Operation timed out

    During handling of the above exception, another exception occurred:

    Traceback (most recent call last):
      File "/Library/Frameworks/Python.framework/Versions/3.4/lib/python3.4/site-packages/requests/adapters.py", line 403, in send
        timeout=timeout
      File "/Library/Frameworks/Python.framework/Versions/3.4/lib/python3.4/site-packages/requests/packages/urllib3/connectionpool.py", line 623, in urlopen
        _stacktrace=sys.exc_info()[2])
      File "/Library/Frameworks/Python.framework/Versions/3.4/lib/python3.4/site-packages/requests/packages/urllib3/util/retry.py", line 281, in increment
        raise MaxRetryError(_pool, url, error or ResponseError(cause))
    requests.packages.urllib3.exceptions.MaxRetryError: HTTPConnectionPool(host='10.101.0.203', port=8080): Max retries exceeded with url: /imcrs/plat/res/device?resPrivilegeFilter=false&ip=10.101.0.1&start=0&size=1000&orderBy=id&desc=false&total=false (Caused by NewConnectionError('<requests.packages.urllib3.connection.HTTPConnection object at 0x1031af1d0>: Failed to establish a new connection: [Errno 60] Operation timed out',))

    During handling of the above exception, another exception occurred:

    Traceback (most recent call last):
      File "/Library/Frameworks/Python.framework/Versions/3.4/lib/python3.4/doctest.py", line 1318, in __run
        compileflags, 1), test.globs)
      File "<doctest default[0]>", line 1, in <module>
        get_dev_details('10.101.0.1', auth.creds, auth.url)
      File "/Library/Frameworks/Python.framework/Versions/3.4/lib/python3.4/site-packages/pyhpeimc/plat/device.py", line 74, in get_dev_details
        r = requests.get(f_url, auth=auth, headers=HEADERS)
      File "/Library/Frameworks/Python.framework/Versions/3.4/lib/python3.4/site-packages/requests/api.py", line 71, in get
        return request('get', url, params=params, **kwargs)
      File "/Library/Frameworks/Python.framework/Versions/3.4/lib/python3.4/site-packages/requests/api.py", line 57, in request
        return session.request(method=method, url=url, **kwargs)
      File "/Library/Frameworks/Python.framework/Versions/3.4/lib/python3.4/site-packages/requests/sessions.py", line 475, in request
        resp = self.send(prep, **send_kwargs)
      File "/Library/Frameworks/Python.framework/Versions/3.4/lib/python3.4/site-packages/requests/sessions.py", line 585, in send
        r = adapter.send(request, **kwargs)
      File "/Library/Frameworks/Python.framework/Versions/3.4/lib/python3.4/site-packages/requests/adapters.py", line 467, in send
        raise ConnectionError(e, request=request)
    requests.exceptions.ConnectionError: HTTPConnectionPool(host='10.101.0.203', port=8080): Max retries exceeded with url: /imcrs/plat/res/device?resPrivilegeFilter=false&ip=10.101.0.1&start=0&size=1000&orderBy=id&desc=false&total=false (Caused by NewConnectionError('<requests.packages.urllib3.connection.HTTPConnection object at 0x1031af1d0>: Failed to establish a new connection: [Errno 60] Operation timed out',))
**********************************************************************
File "pyhpeimc.plat.device.rst", line ?, in default
Failed example:
    get_dev_details('8.8.8.8', auth.creds, auth.url)
Exception raised:
    Traceback (most recent call last):
      File "/Library/Frameworks/Python.framework/Versions/3.4/lib/python3.4/site-packages/requests/packages/urllib3/connection.py", line 142, in _new_conn
        (self.host, self.port), self.timeout, **extra_kw)
      File "/Library/Frameworks/Python.framework/Versions/3.4/lib/python3.4/site-packages/requests/packages/urllib3/util/connection.py", line 91, in create_connection
        raise err
      File "/Library/Frameworks/Python.framework/Versions/3.4/lib/python3.4/site-packages/requests/packages/urllib3/util/connection.py", line 81, in create_connection
        sock.connect(sa)
    TimeoutError: [Errno 60] Operation timed out

    During handling of the above exception, another exception occurred:

    Traceback (most recent call last):
      File "/Library/Frameworks/Python.framework/Versions/3.4/lib/python3.4/site-packages/requests/packages/urllib3/connectionpool.py", line 578, in urlopen
        chunked=chunked)
      File "/Library/Frameworks/Python.framework/Versions/3.4/lib/python3.4/site-packages/requests/packages/urllib3/connectionpool.py", line 362, in _make_request
        conn.request(method, url, **httplib_request_kw)
      File "/Library/Frameworks/Python.framework/Versions/3.4/lib/python3.4/http/client.py", line 1088, in request
        self._send_request(method, url, body, headers)
      File "/Library/Frameworks/Python.framework/Versions/3.4/lib/python3.4/http/client.py", line 1126, in _send_request
        self.endheaders(body)
      File "/Library/Frameworks/Python.framework/Versions/3.4/lib/python3.4/http/client.py", line 1084, in endheaders
        self._send_output(message_body)
      File "/Library/Frameworks/Python.framework/Versions/3.4/lib/python3.4/http/client.py", line 922, in _send_output
        self.send(msg)
      File "/Library/Frameworks/Python.framework/Versions/3.4/lib/python3.4/http/client.py", line 857, in send
        self.connect()
      File "/Library/Frameworks/Python.framework/Versions/3.4/lib/python3.4/site-packages/requests/packages/urllib3/connection.py", line 167, in connect
        conn = self._new_conn()
      File "/Library/Frameworks/Python.framework/Versions/3.4/lib/python3.4/site-packages/requests/packages/urllib3/connection.py", line 151, in _new_conn
        self, "Failed to establish a new connection: %s" % e)
    requests.packages.urllib3.exceptions.NewConnectionError: <requests.packages.urllib3.connection.HTTPConnection object at 0x107141908>: Failed to establish a new connection: [Errno 60] Operation timed out

    During handling of the above exception, another exception occurred:

    Traceback (most recent call last):
      File "/Library/Frameworks/Python.framework/Versions/3.4/lib/python3.4/site-packages/requests/adapters.py", line 403, in send
        timeout=timeout
      File "/Library/Frameworks/Python.framework/Versions/3.4/lib/python3.4/site-packages/requests/packages/urllib3/connectionpool.py", line 623, in urlopen
        _stacktrace=sys.exc_info()[2])
      File "/Library/Frameworks/Python.framework/Versions/3.4/lib/python3.4/site-packages/requests/packages/urllib3/util/retry.py", line 281, in increment
        raise MaxRetryError(_pool, url, error or ResponseError(cause))
    requests.packages.urllib3.exceptions.MaxRetryError: HTTPConnectionPool(host='10.101.0.203', port=8080): Max retries exceeded with url: /imcrs/plat/res/device?resPrivilegeFilter=false&ip=8.8.8.8&start=0&size=1000&orderBy=id&desc=false&total=false (Caused by NewConnectionError('<requests.packages.urllib3.connection.HTTPConnection object at 0x107141908>: Failed to establish a new connection: [Errno 60] Operation timed out',))

    During handling of the above exception, another exception occurred:

    Traceback (most recent call last):
      File "/Library/Frameworks/Python.framework/Versions/3.4/lib/python3.4/doctest.py", line 1318, in __run
        compileflags, 1), test.globs)
      File "<doctest default[0]>", line 1, in <module>
        get_dev_details('8.8.8.8', auth.creds, auth.url)
      File "/Library/Frameworks/Python.framework/Versions/3.4/lib/python3.4/site-packages/pyhpeimc/plat/device.py", line 74, in get_dev_details
        r = requests.get(f_url, auth=auth, headers=HEADERS)
      File "/Library/Frameworks/Python.framework/Versions/3.4/lib/python3.4/site-packages/requests/api.py", line 71, in get
        return request('get', url, params=params, **kwargs)
      File "/Library/Frameworks/Python.framework/Versions/3.4/lib/python3.4/site-packages/requests/api.py", line 57, in request
        return session.request(method=method, url=url, **kwargs)
      File "/Library/Frameworks/Python.framework/Versions/3.4/lib/python3.4/site-packages/requests/sessions.py", line 475, in request
        resp = self.send(prep, **send_kwargs)
      File "/Library/Frameworks/Python.framework/Versions/3.4/lib/python3.4/site-packages/requests/sessions.py", line 585, in send
        r = adapter.send(request, **kwargs)
      File "/Library/Frameworks/Python.framework/Versions/3.4/lib/python3.4/site-packages/requests/adapters.py", line 467, in send
        raise ConnectionError(e, request=request)
    requests.exceptions.ConnectionError: HTTPConnectionPool(host='10.101.0.203', port=8080): Max retries exceeded with url: /imcrs/plat/res/device?resPrivilegeFilter=false&ip=8.8.8.8&start=0&size=1000&orderBy=id&desc=false&total=false (Caused by NewConnectionError('<requests.packages.urllib3.connection.HTTPConnection object at 0x107141908>: Failed to establish a new connection: [Errno 60] Operation timed out',))
**********************************************************************
File "pyhpeimc.plat.device.rst", line ?, in default
Failed example:
    get_dev_interface('15', auth.creds, auth.url)
Exception raised:
    Traceback (most recent call last):
      File "/Library/Frameworks/Python.framework/Versions/3.4/lib/python3.4/site-packages/requests/packages/urllib3/connection.py", line 142, in _new_conn
        (self.host, self.port), self.timeout, **extra_kw)
      File "/Library/Frameworks/Python.framework/Versions/3.4/lib/python3.4/site-packages/requests/packages/urllib3/util/connection.py", line 91, in create_connection
        raise err
      File "/Library/Frameworks/Python.framework/Versions/3.4/lib/python3.4/site-packages/requests/packages/urllib3/util/connection.py", line 81, in create_connection
        sock.connect(sa)
    TimeoutError: [Errno 60] Operation timed out

    During handling of the above exception, another exception occurred:

    Traceback (most recent call last):
      File "/Library/Frameworks/Python.framework/Versions/3.4/lib/python3.4/site-packages/requests/packages/urllib3/connectionpool.py", line 578, in urlopen
        chunked=chunked)
      File "/Library/Frameworks/Python.framework/Versions/3.4/lib/python3.4/site-packages/requests/packages/urllib3/connectionpool.py", line 362, in _make_request
        conn.request(method, url, **httplib_request_kw)
      File "/Library/Frameworks/Python.framework/Versions/3.4/lib/python3.4/http/client.py", line 1088, in request
        self._send_request(method, url, body, headers)
      File "/Library/Frameworks/Python.framework/Versions/3.4/lib/python3.4/http/client.py", line 1126, in _send_request
        self.endheaders(body)
      File "/Library/Frameworks/Python.framework/Versions/3.4/lib/python3.4/http/client.py", line 1084, in endheaders
        self._send_output(message_body)
      File "/Library/Frameworks/Python.framework/Versions/3.4/lib/python3.4/http/client.py", line 922, in _send_output
        self.send(msg)
      File "/Library/Frameworks/Python.framework/Versions/3.4/lib/python3.4/http/client.py", line 857, in send
        self.connect()
      File "/Library/Frameworks/Python.framework/Versions/3.4/lib/python3.4/site-packages/requests/packages/urllib3/connection.py", line 167, in connect
        conn = self._new_conn()
      File "/Library/Frameworks/Python.framework/Versions/3.4/lib/python3.4/site-packages/requests/packages/urllib3/connection.py", line 151, in _new_conn
        self, "Failed to establish a new connection: %s" % e)
    requests.packages.urllib3.exceptions.NewConnectionError: <requests.packages.urllib3.connection.HTTPConnection object at 0x1031afbe0>: Failed to establish a new connection: [Errno 60] Operation timed out

    During handling of the above exception, another exception occurred:

    Traceback (most recent call last):
      File "/Library/Frameworks/Python.framework/Versions/3.4/lib/python3.4/site-packages/requests/adapters.py", line 403, in send
        timeout=timeout
      File "/Library/Frameworks/Python.framework/Versions/3.4/lib/python3.4/site-packages/requests/packages/urllib3/connectionpool.py", line 623, in urlopen
        _stacktrace=sys.exc_info()[2])
      File "/Library/Frameworks/Python.framework/Versions/3.4/lib/python3.4/site-packages/requests/packages/urllib3/util/retry.py", line 281, in increment
        raise MaxRetryError(_pool, url, error or ResponseError(cause))
    requests.packages.urllib3.exceptions.MaxRetryError: HTTPConnectionPool(host='10.101.0.203', port=8080): Max retries exceeded with url: /imcrs/plat/res/device/15/interface?start=0&size=1000&desc=false&total=false (Caused by NewConnectionError('<requests.packages.urllib3.connection.HTTPConnection object at 0x1031afbe0>: Failed to establish a new connection: [Errno 60] Operation timed out',))

    During handling of the above exception, another exception occurred:

    Traceback (most recent call last):
      File "/Library/Frameworks/Python.framework/Versions/3.4/lib/python3.4/doctest.py", line 1318, in __run
        compileflags, 1), test.globs)
      File "<doctest default[0]>", line 1, in <module>
        get_dev_interface('15', auth.creds, auth.url)
      File "/Library/Frameworks/Python.framework/Versions/3.4/lib/python3.4/site-packages/pyhpeimc/plat/device.py", line 1060, in get_dev_interface
        r = requests.get(f_url, auth=auth, headers=HEADERS)
      File "/Library/Frameworks/Python.framework/Versions/3.4/lib/python3.4/site-packages/requests/api.py", line 71, in get
        return request('get', url, params=params, **kwargs)
      File "/Library/Frameworks/Python.framework/Versions/3.4/lib/python3.4/site-packages/requests/api.py", line 57, in request
        return session.request(method=method, url=url, **kwargs)
      File "/Library/Frameworks/Python.framework/Versions/3.4/lib/python3.4/site-packages/requests/sessions.py", line 475, in request
        resp = self.send(prep, **send_kwargs)
      File "/Library/Frameworks/Python.framework/Versions/3.4/lib/python3.4/site-packages/requests/sessions.py", line 585, in send
        r = adapter.send(request, **kwargs)
      File "/Library/Frameworks/Python.framework/Versions/3.4/lib/python3.4/site-packages/requests/adapters.py", line 467, in send
        raise ConnectionError(e, request=request)
    requests.exceptions.ConnectionError: HTTPConnectionPool(host='10.101.0.203', port=8080): Max retries exceeded with url: /imcrs/plat/res/device/15/interface?start=0&size=1000&desc=false&total=false (Caused by NewConnectionError('<requests.packages.urllib3.connection.HTTPConnection object at 0x1031afbe0>: Failed to establish a new connection: [Errno 60] Operation timed out',))
**********************************************************************
File "pyhpeimc.plat.device.rst", line ?, in default
Failed example:
    get_dev_mac_learn('10', auth.creds, auth.url)
Expected:
    [{'device': 'http://kontrolissues.thruhere.net:8086/imcrs/plat/res/device/10',
Got:
    "Error:\nHTTPConnectionPool(host='10.101.0.203', port=8080): Max retries exceeded with url: /imcrs/res/access/ipMacLearn/10 (Caused by NewConnectionError('<requests.packages.urllib3.connection.HTTPConnection object at 0x107160240>: Failed to establish a new connection: [Errno 60] Operation timed out',)) get_dev_mac_learn: An Error has occured"
**********************************************************************
File "pyhpeimc.plat.device.rst", line ?, in default
Failed example:
    get_dev_start_config('10', auth.creds, auth.url)
Exception raised:
    Traceback (most recent call last):
      File "/Library/Frameworks/Python.framework/Versions/3.4/lib/python3.4/site-packages/requests/packages/urllib3/connection.py", line 142, in _new_conn
        (self.host, self.port), self.timeout, **extra_kw)
      File "/Library/Frameworks/Python.framework/Versions/3.4/lib/python3.4/site-packages/requests/packages/urllib3/util/connection.py", line 91, in create_connection
        raise err
      File "/Library/Frameworks/Python.framework/Versions/3.4/lib/python3.4/site-packages/requests/packages/urllib3/util/connection.py", line 81, in create_connection
        sock.connect(sa)
    OSError: [Errno 50] Network is down

    During handling of the above exception, another exception occurred:

    Traceback (most recent call last):
      File "/Library/Frameworks/Python.framework/Versions/3.4/lib/python3.4/site-packages/requests/packages/urllib3/connectionpool.py", line 578, in urlopen
        chunked=chunked)
      File "/Library/Frameworks/Python.framework/Versions/3.4/lib/python3.4/site-packages/requests/packages/urllib3/connectionpool.py", line 362, in _make_request
        conn.request(method, url, **httplib_request_kw)
      File "/Library/Frameworks/Python.framework/Versions/3.4/lib/python3.4/http/client.py", line 1088, in request
        self._send_request(method, url, body, headers)
      File "/Library/Frameworks/Python.framework/Versions/3.4/lib/python3.4/http/client.py", line 1126, in _send_request
        self.endheaders(body)
      File "/Library/Frameworks/Python.framework/Versions/3.4/lib/python3.4/http/client.py", line 1084, in endheaders
        self._send_output(message_body)
      File "/Library/Frameworks/Python.framework/Versions/3.4/lib/python3.4/http/client.py", line 922, in _send_output
        self.send(msg)
      File "/Library/Frameworks/Python.framework/Versions/3.4/lib/python3.4/http/client.py", line 857, in send
        self.connect()
      File "/Library/Frameworks/Python.framework/Versions/3.4/lib/python3.4/site-packages/requests/packages/urllib3/connection.py", line 167, in connect
        conn = self._new_conn()
      File "/Library/Frameworks/Python.framework/Versions/3.4/lib/python3.4/site-packages/requests/packages/urllib3/connection.py", line 151, in _new_conn
        self, "Failed to establish a new connection: %s" % e)
    requests.packages.urllib3.exceptions.NewConnectionError: <requests.packages.urllib3.connection.HTTPConnection object at 0x107160a58>: Failed to establish a new connection: [Errno 50] Network is down

    During handling of the above exception, another exception occurred:

    Traceback (most recent call last):
      File "/Library/Frameworks/Python.framework/Versions/3.4/lib/python3.4/site-packages/requests/adapters.py", line 403, in send
        timeout=timeout
      File "/Library/Frameworks/Python.framework/Versions/3.4/lib/python3.4/site-packages/requests/packages/urllib3/connectionpool.py", line 623, in urlopen
        _stacktrace=sys.exc_info()[2])
      File "/Library/Frameworks/Python.framework/Versions/3.4/lib/python3.4/site-packages/requests/packages/urllib3/util/retry.py", line 281, in increment
        raise MaxRetryError(_pool, url, error or ResponseError(cause))
    requests.packages.urllib3.exceptions.MaxRetryError: HTTPConnectionPool(host='10.101.0.203', port=8080): Max retries exceeded with url: /imcrs/icc/deviceCfg/10/currentStart (Caused by NewConnectionError('<requests.packages.urllib3.connection.HTTPConnection object at 0x107160a58>: Failed to establish a new connection: [Errno 50] Network is down',))

    During handling of the above exception, another exception occurred:

    Traceback (most recent call last):
      File "/Library/Frameworks/Python.framework/Versions/3.4/lib/python3.4/doctest.py", line 1318, in __run
        compileflags, 1), test.globs)
      File "<doctest default[0]>", line 1, in <module>
        get_dev_start_config('10', auth.creds, auth.url)
      File "/Library/Frameworks/Python.framework/Versions/3.4/lib/python3.4/site-packages/pyhpeimc/plat/device.py", line 1146, in get_dev_start_config
        r = requests.get(f_url, auth=auth, headers=HEADERS)
      File "/Library/Frameworks/Python.framework/Versions/3.4/lib/python3.4/site-packages/requests/api.py", line 71, in get
        return request('get', url, params=params, **kwargs)
      File "/Library/Frameworks/Python.framework/Versions/3.4/lib/python3.4/site-packages/requests/api.py", line 57, in request
        return session.request(method=method, url=url, **kwargs)
      File "/Library/Frameworks/Python.framework/Versions/3.4/lib/python3.4/site-packages/requests/sessions.py", line 475, in request
        resp = self.send(prep, **send_kwargs)
      File "/Library/Frameworks/Python.framework/Versions/3.4/lib/python3.4/site-packages/requests/sessions.py", line 585, in send
        r = adapter.send(request, **kwargs)
      File "/Library/Frameworks/Python.framework/Versions/3.4/lib/python3.4/site-packages/requests/adapters.py", line 467, in send
        raise ConnectionError(e, request=request)
    requests.exceptions.ConnectionError: HTTPConnectionPool(host='10.101.0.203', port=8080): Max retries exceeded with url: /imcrs/icc/deviceCfg/10/currentStart (Caused by NewConnectionError('<requests.packages.urllib3.connection.HTTPConnection object at 0x107160a58>: Failed to establish a new connection: [Errno 50] Network is down',))
**********************************************************************
File "pyhpeimc.plat.device.rst", line ?, in default
Failed example:
    run_dev_cmd('10', cmd_list, auth.creds, auth.url)
Exception raised:
    Traceback (most recent call last):
      File "/Library/Frameworks/Python.framework/Versions/3.4/lib/python3.4/site-packages/requests/packages/urllib3/connection.py", line 142, in _new_conn
        (self.host, self.port), self.timeout, **extra_kw)
      File "/Library/Frameworks/Python.framework/Versions/3.4/lib/python3.4/site-packages/requests/packages/urllib3/util/connection.py", line 91, in create_connection
        raise err
      File "/Library/Frameworks/Python.framework/Versions/3.4/lib/python3.4/site-packages/requests/packages/urllib3/util/connection.py", line 81, in create_connection
        sock.connect(sa)
    OSError: [Errno 51] Network is unreachable

    During handling of the above exception, another exception occurred:

    Traceback (most recent call last):
      File "/Library/Frameworks/Python.framework/Versions/3.4/lib/python3.4/site-packages/requests/packages/urllib3/connectionpool.py", line 578, in urlopen
        chunked=chunked)
      File "/Library/Frameworks/Python.framework/Versions/3.4/lib/python3.4/site-packages/requests/packages/urllib3/connectionpool.py", line 362, in _make_request
        conn.request(method, url, **httplib_request_kw)
      File "/Library/Frameworks/Python.framework/Versions/3.4/lib/python3.4/http/client.py", line 1088, in request
        self._send_request(method, url, body, headers)
      File "/Library/Frameworks/Python.framework/Versions/3.4/lib/python3.4/http/client.py", line 1126, in _send_request
        self.endheaders(body)
      File "/Library/Frameworks/Python.framework/Versions/3.4/lib/python3.4/http/client.py", line 1084, in endheaders
        self._send_output(message_body)
      File "/Library/Frameworks/Python.framework/Versions/3.4/lib/python3.4/http/client.py", line 922, in _send_output
        self.send(msg)
      File "/Library/Frameworks/Python.framework/Versions/3.4/lib/python3.4/http/client.py", line 857, in send
        self.connect()
      File "/Library/Frameworks/Python.framework/Versions/3.4/lib/python3.4/site-packages/requests/packages/urllib3/connection.py", line 167, in connect
        conn = self._new_conn()
      File "/Library/Frameworks/Python.framework/Versions/3.4/lib/python3.4/site-packages/requests/packages/urllib3/connection.py", line 151, in _new_conn
        self, "Failed to establish a new connection: %s" % e)
    requests.packages.urllib3.exceptions.NewConnectionError: <requests.packages.urllib3.connection.HTTPConnection object at 0x1071642b0>: Failed to establish a new connection: [Errno 51] Network is unreachable

    During handling of the above exception, another exception occurred:

    Traceback (most recent call last):
      File "/Library/Frameworks/Python.framework/Versions/3.4/lib/python3.4/site-packages/requests/adapters.py", line 403, in send
        timeout=timeout
      File "/Library/Frameworks/Python.framework/Versions/3.4/lib/python3.4/site-packages/requests/packages/urllib3/connectionpool.py", line 623, in urlopen
        _stacktrace=sys.exc_info()[2])
      File "/Library/Frameworks/Python.framework/Versions/3.4/lib/python3.4/site-packages/requests/packages/urllib3/util/retry.py", line 281, in increment
        raise MaxRetryError(_pool, url, error or ResponseError(cause))
    requests.packages.urllib3.exceptions.MaxRetryError: HTTPConnectionPool(host='10.101.0.203', port=8080): Max retries exceeded with url: /imcrs/icc/confFile/executeCmd (Caused by NewConnectionError('<requests.packages.urllib3.connection.HTTPConnection object at 0x1071642b0>: Failed to establish a new connection: [Errno 51] Network is unreachable',))

    During handling of the above exception, another exception occurred:

    Traceback (most recent call last):
      File "/Library/Frameworks/Python.framework/Versions/3.4/lib/python3.4/doctest.py", line 1318, in __run
        compileflags, 1), test.globs)
      File "<doctest default[0]>", line 1, in <module>
        run_dev_cmd('10', cmd_list, auth.creds, auth.url)
      File "/Library/Frameworks/Python.framework/Versions/3.4/lib/python3.4/site-packages/pyhpeimc/plat/device.py", line 1687, in run_dev_cmd
        r = requests.post(f_url, data=payload, auth=auth, headers=HEADERS)
      File "/Library/Frameworks/Python.framework/Versions/3.4/lib/python3.4/site-packages/requests/api.py", line 111, in post
        return request('post', url, data=data, json=json, **kwargs)
      File "/Library/Frameworks/Python.framework/Versions/3.4/lib/python3.4/site-packages/requests/api.py", line 57, in request
        return session.request(method=method, url=url, **kwargs)
      File "/Library/Frameworks/Python.framework/Versions/3.4/lib/python3.4/site-packages/requests/sessions.py", line 475, in request
        resp = self.send(prep, **send_kwargs)
      File "/Library/Frameworks/Python.framework/Versions/3.4/lib/python3.4/site-packages/requests/sessions.py", line 585, in send
        r = adapter.send(request, **kwargs)
      File "/Library/Frameworks/Python.framework/Versions/3.4/lib/python3.4/site-packages/requests/adapters.py", line 467, in send
        raise ConnectionError(e, request=request)
    requests.exceptions.ConnectionError: HTTPConnectionPool(host='10.101.0.203', port=8080): Max retries exceeded with url: /imcrs/icc/confFile/executeCmd (Caused by NewConnectionError('<requests.packages.urllib3.connection.HTTPConnection object at 0x1071642b0>: Failed to establish a new connection: [Errno 51] Network is unreachable',))
**********************************************************************
1 items had failures:
   6 of  36 in default
36 tests in 1 items.
30 passed and 6 failed.
***Test Failed*** 6 failures.

Doctest summary
===============
   38 tests
    8 failures in tests
    0 failures in setup code
    0 failures in cleanup code
